<?xml version="1.0" encoding="utf-8"?>
<!-- This URDF was automatically created by SolidWorks to URDF Exporter! Originally created by Stephen Brawner (brawner@gmail.com) 
     Commit Version: 1.6.0-4-g7f85cfe  Build Version: 1.6.7995.38578
     For more information, please see http://wiki.ros.org/sw_urdf_exporter -->
<robot
  name="robot_description">
  <link
    name="base_link">
    <inertial>
      <origin
        xyz="-0.0085571580084014 -9.57377255938964E-05 0.158358924022717"
        rpy="0 0 0" />
      <mass
        value="36.4090186352555" />
      <inertia
        ixx="1.14989797110002"
        ixy="-2.43735391975683E-05"
        ixz="0.0182296282265288"
        iyy="0.875741628239762"
        iyz="-3.3601253494027E-05"
        izz="1.2152774654334" />
    </inertial>
    <visual>
      <origin
        xyz="0 0 0"
        rpy="0 0 0" />
      <geometry>
        <mesh
          filename="package://robot_description/meshes/base_link.STL" />
      </geometry>
      <material
        name="">
        <color
          rgba="0.792156862745098 0.819607843137255 0.933333333333333 1" />
      </material>
    </visual>
    <collision>
      <origin
        xyz="0 0 0"
        rpy="0 0 0" />
      <geometry>
        <mesh
          filename="package://robot_description/meshes/base_link.STL" />
      </geometry>
    </collision>
  </link>
  <link
    name="link_BR">
    <inertial>
      <origin
        xyz="-0.65034495600087 0.845 -2.77555756156289E-17"
        rpy="0 0 0" />
      <mass
        value="8.03286499782857" />
      <inertia
        ixx="0.0518365067203933"
        ixy="2.81782289636273E-18"
        ixz="2.12705860438942E-18"
        iyy="0.0735497696989295"
        iyz="-2.9413891315951E-18"
        izz="0.0518365067203933" />
    </inertial>
    <visual>
      <origin
        xyz="0 0 0"
        rpy="0 0 0" />
      <geometry>
        <mesh
          filename="package://robot_description/meshes/link_BR.STL" />
      </geometry>
      <material
        name="">
        <color
          rgba="0.792156862745098 0.819607843137255 0.933333333333333 1" />
      </material>
    </visual>
    <collision>
      <origin
        xyz="0 0 0"
        rpy="0 0 0" />
      <geometry>
        <mesh
          filename="package://robot_description/meshes/link_BR.STL" />
      </geometry>
    </collision>
  </link>
  <joint
    name="joint_BR"
    type="continuous">
    <origin
      xyz="0.29061 -0.46009 0.43026"
      rpy="0 0 0" />
    <parent
      link="base_link" />
    <child
      link="link_BR" />
    <axis
      xyz="0 1 0" />
  </joint>
  <link
    name="link_BL">
    <inertial>
      <origin
        xyz="-0.65034495600087 -0.845 -5.55111512312578E-17"
        rpy="0 0 0" />
      <mass
        value="8.03286499782856" />
      <inertia
        ixx="0.0518365067203933"
        ixy="7.83710860584171E-19"
        ixz="1.21760986167806E-17"
        iyy="0.0735497696989294"
        iyz="3.18550845030505E-19"
        izz="0.0518365067203932" />
    </inertial>
    <visual>
      <origin
        xyz="0 0 0"
        rpy="0 0 0" />
      <geometry>
        <mesh
          filename="package://robot_description/meshes/link_BL.STL" />
      </geometry>
      <material
        name="">
        <color
          rgba="0.792156862745098 0.819607843137255 0.933333333333333 1" />
      </material>
    </visual>
    <collision>
      <origin
        xyz="0 0 0"
        rpy="0 0 0" />
      <geometry>
        <mesh
          filename="package://robot_description/meshes/link_BL.STL" />
      </geometry>
    </collision>
  </link>
  <joint
    name="joint_BL"
    type="continuous">
    <origin
      xyz="0.29061 0.45991 0.43026"
      rpy="0 0 0" />
    <parent
      link="base_link" />
    <child
      link="link_BL" />
    <axis
      xyz="0 1 0" />
  </joint>
  <link
    name="link_FR">
    <inertial>
      <origin
        xyz="0.65034495600087 0.845 1.66533453693773E-16"
        rpy="0 0 0" />
      <mass
        value="8.03286499782857" />
      <inertia
        ixx="0.0518365067203933"
        ixy="2.80334530458947E-18"
        ixz="2.21023564860025E-17"
        iyy="0.0735497696989295"
        iyz="-1.51379332393697E-18"
        izz="0.0518365067203933" />
    </inertial>
    <visual>
      <origin
        xyz="0 0 0"
        rpy="0 0 0" />
      <geometry>
        <mesh
          filename="package://robot_description/meshes/link_FR.STL" />
      </geometry>
      <material
        name="">
        <color
          rgba="0.792156862745098 0.819607843137255 0.933333333333333 1" />
      </material>
    </visual>
    <collision>
      <origin
        xyz="0 0 0"
        rpy="0 0 0" />
      <geometry>
        <mesh
          filename="package://robot_description/meshes/link_FR.STL" />
      </geometry>
    </collision>
  </link>
  <joint
    name="joint_FR"
    type="continuous">
    <origin
      xyz="-0.35973 -0.46009 0.43026"
      rpy="0 0 0" />
    <parent
      link="base_link" />
    <child
      link="link_FR" />
    <axis
      xyz="0 1 0" />
  </joint>
  <link
    name="link_FL">
    <inertial>
      <origin
        xyz="0.65034495600087 -0.845 1.38777878078145E-16"
        rpy="0 0 0" />
      <mass
        value="8.03286499782857" />
      <inertia
        ixx="0.0518365067203933"
        ixy="3.89221565430702E-19"
        ixz="-4.21360106871541E-18"
        iyy="0.0735497696989295"
        iyz="3.94929111657312E-19"
        izz="0.0518365067203933" />
    </inertial>
    <visual>
      <origin
        xyz="0 0 0"
        rpy="0 0 0" />
      <geometry>
        <mesh
          filename="package://robot_description/meshes/link_FL.STL" />
      </geometry>
      <material
        name="">
        <color
          rgba="0.792156862745098 0.819607843137255 0.933333333333333 1" />
      </material>
    </visual>
    <collision>
      <origin
        xyz="0 0 0"
        rpy="0 0 0" />
      <geometry>
        <mesh
          filename="package://robot_description/meshes/link_FL.STL" />
      </geometry>
    </collision>
  </link>
  <joint
    name="joint_FL"
    type="continuous">
    <origin
      xyz="-0.35973 0.45991 0.43026"
      rpy="0 0 0" />
    <parent
      link="base_link" />
    <child
      link="link_FL" />
    <axis
      xyz="0 1 0" />
  </joint>
</robot>